Workbook

Sheet Item Master
A1: IGI — INVENTORY ITEM MASTER CATALOG
A2: Mumbai HQ maintains this master. Yellow cells = fill in costs. Blue = inputs you may change.
A3: # | B3: ITEM NAME | C3: CATEGORY | D3: COURSE | E3: TYPE | F3: UNIT COST (₹) | G3: QTY PER STUDENT | H3: QTY PER CLASSROOM | I3: REORDER LEVEL | J3: LEAD TIME (days) | K3: SUPPLIER / VENDOR | L3: NOTES
A4: 1 | B4: Education Brochure | C4: Promotion Collateral | D4: General | E4: Consumable | G4: 1 | H4: 0 | I4: 50 | J4: 7 | L4: For walk-ins & events
A5: 2 | B5: Spiral Note Book | C5: Promotion Collateral | D5: General | E5: Consumable | G5: 1 | H5: 0 | I5: 30 | J5: 7 | L5: Given at enrollment
A6: 3 | B6: Pens | C6: Promotion Collateral | D6: General | E6: Consumable | G6: 2 | H6: 0 | I6: 100 | J6: 5
A7: 4 | B7: Diamond Grading Manual | C7: Course Collateral | D7: Diamond Graduate | E7: Consumable | G7: 1 | H7: 0 | I7: 10 | J7: 14
A8: 5 | B8: RBC Work Sheet | C8: Course Collateral | D8: Diamond Graduate | E8: Consumable | G8: 2 | H8: 0 | I8: 20 | J8: 7
A9: 6 | B9: Fancy Shape Work Sheet | C9: Course Collateral | D9: Diamond Graduate | E9: Consumable | G9: 2 | H9: 0 | I9: 20 | J9: 7
A10: 7 | B10: Fine Tip Tweezer | C10: Course Collateral | D10: Diamond Graduate | E10: Consumable | G10: 1 | H10: 0 | I10: 10 | J10: 10
A11: 8 | B11: Color Card | C11: Course Collateral | D11: Diamond Graduate | E11: Consumable | G11: 1 | H11: 0 | I11: 10 | J11: 14
A12: 9 | B12: Diamond Grading Kit | C12: Course Collateral | D12: Diamond Graduate | E12: Kit | G12: 1 | H12: 0 | I12: 5 | J12: 21 | L12: Full kit per student
A13: 10 | B13: Assortment Pads | C13: Classroom Equipment | D13: Diamond Graduate | E13: Reusable | G13: 0 | H13: 4 | I13: 2 | J13: 14 | L13: 4 per classroom
A14: 11 | B14: Grading Lamps | C14: Classroom Equipment | D14: Diamond Graduate | E14: Reusable | G14: 0 | H14: 6 | I14: 1 | J14: 21 | L14: 6 per classroom
A15: 12 | B15: UV Lamp | C15: Classroom Equipment | D15: Diamond Graduate | E15: Reusable | G15: 0 | H15: 1 | I15: 1 | J15: 14 | L15: 1 per classroom
A16: 13 | B16: Microscope | C16: Classroom Equipment | D16: Diamond Graduate | E16: Reusable | G16: 0 | H16: 2 | I16: 1 | J16: 30 | L16: 2 per classroom
A17: 14 | B17: Dial Gauge | C17: Classroom Equipment | D17: Diamond Graduate | E17: Reusable | G17: 0 | H17: 2 | I17: 1 | J17: 21
A18: 15 | B18: Jewelry Gauge | C18: Classroom Equipment | D18: Diamond Graduate | E18: Reusable | G18: 0 | H18: 2 | I18: 1 | J18: 21
A19: 16 | B19: Colored Stone Manual | C19: Course Collateral | D19: Colored Stone Graduate | E19: Consumable | G19: 1 | H19: 0 | I19: 10 | J19: 14
A20: 17 | B20: CS Work Sheet | C20: Course Collateral | D20: Colored Stone Graduate | E20: Consumable | G20: 2 | H20: 0 | I20: 20 | J20: 7
A21: 18 | B21: Color Chart | C21: Course Collateral | D21: Colored Stone Graduate | E21: Consumable | G21: 1 | H21: 0 | I21: 10 | J21: 14
A22: 19 | B22: Colored Stone Grading Kit | C22: Course Collateral | D22: Colored Stone Graduate | E22: Kit | G22: 1 | H22: 0 | I22: 5 | J22: 21
A23: 20 | B23: Assortment Pads | C23: Classroom Equipment | D23: Colored Stone Graduate | E23: Reusable | G23: 0 | H23: 4 | I23: 1 | J23: 14
A24: 21 | B24: Grading Lamps | C24: Classroom Equipment | D24: Colored Stone Graduate | E24: Reusable | G24: 0 | H24: 6 | I24: 1 | J24: 21
A25: 22 | B25: UV Lamp | C25: Classroom Equipment | D25: Colored Stone Graduate | E25: Reusable | G25: 0 | H25: 1 | I25: 1 | J25: 14
A26: 23 | B26: SG Kit / Weighing Scale | C26: Classroom Equipment | D26: Colored Stone Graduate | E26: Reusable | G26: 0 | H26: 1 | I26: 1 | J26: 30
A27: 24 | B27: Microscope | C27: Classroom Equipment | D27: Colored Stone Graduate | E27: Reusable | G27: 0 | H27: 2 | I27: 1 | J27: 30
A28: 25 | B28: Refractometer | C28: Classroom Equipment | D28: Colored Stone Graduate | E28: Reusable | G28: 0 | H28: 1 | I28: 1 | J28: 30
... A34: 31 | B34: Portfolio Bag | C34: Course Collateral | D34: Jewelry Design Graduate | E34: Consumable | G34: 1 | H34: 0 | I34: 5 | J34: 14
A35: 32 | B35: Vellum Sheets | C35: Course Collateral | D35: Jewelry Design Graduate | E35: Consumable | G35: 10 | H35: 0 | I35: 50 | J35: 7 | L35: Pack of 10 per student
A36: 33 | B36: A3 Black/Grey Sheets | C36: Course Collateral | D36: Jewelry Design Graduate | E36: Consumable | G36: 5 | H36: 0 | I36: 30 | J36: 7
A37: 34 | B37: Sheet Protectors | C37: Course Collateral | D37: Jewelry Design Graduate | E37: Consumable | G37: 10 | H37: 0 | I37: 50 | J37: 5
A38: 35 | B38: A4 Gateway Sheet | C38: Course Collateral | D38: Jewelry Design Graduate | E38: Consumable | G38: 2 | H38: 0 | I38: 20 | J38: 7
A39: 36 | B39: Grading Lamps | C39: Classroom Equipment | D39: Jewelry Design Graduate | E39: Reusable | G39: 0 | H39: 4 | I39: 1 | J39: 21
A40: 37 | B40: Polished Diamond Grading Manual | C40: Course Collateral | D40: Polished Diamond Grading | E40: Consumable | G40: 1 | H40: 0 | I40: 10 | J40: 14
A41: 38 | B41: RBC Work Sheet | C41: Course Collateral | D41: Polished Diamond Grading | E41: Consumable | G41: 2 | H41: 0 | I41: 20 | J41: 7
A42: 39 | B42: Fancy Shape Work Sheet | C42: Course Collateral | D42: Polished Diamond Grading | E42: Consumable | G42: 2 | H42: 0 | I42: 20 | J42: 7
A43: 40 | B43: Color Card | C43: Course Collateral | D43: Polished Diamond Grading | E43: Consumable | G43: 1 | H43: 0 | I43: 10 | J43: 14
A44: 41 | B44: Diamond Grading Kit | C44: Course Collateral | D44: Polished Diamond Grading | E44: Kit | G44: 1 | H44: 0 | I44: 5 | J44: 21
A45: 42 | B45: Assortment Pads | C45: Classroom Equipment | D45: Polished Diamond Grading | E45: Reusable | G45: 0 | H45: 4 | I45: 1 | J45: 14
...

Sheet Mumbai Stock
A1: IGI — MUMBAI HQ STOCK LEDGER
A2: Update Qty on Hand whenever stock is received or dispatched. Status is auto-calculated.
A3: ITEM NAME | B3: CATEGORY | C3: COURSE | D3: QTY ON HAND | E3: QTY ON ORDER | F3: TOTAL AVAILABLE | G3: REORDER LEVEL | H3: STATUS | I3: UNIT COST (₹) | J3: TOTAL VALUE (₹)
A4: Education Brochure | B4: Promotion Collateral | C4: General | D4: 0 | E4: 0 | F4: =D4+E4 -> 0 | G4: ='Item Master'!I4 -> 50 | H4: =IF(F4=0,"OUT OF STOCK",IF(F4<=G4,"REORDER","OK")) -> OUT OF STOCK | I4: ='Item Master'!F4 -> 0 | J4: =IF(ISNUMBER(I4),D4*I4,0) -> 0
A5: Spiral Note Book | B5: Promotion Collateral | C5: General | D5: 0 | E5: 0 | F5: =D5+E5 -> 0 | G5: ='Item Master'!I5 -> 30 | H5: =IF(F5=0,"OUT OF STOCK",IF(F5<=G5,"REORDER","OK")) -> OUT OF STOCK | I5: ='Item Master'!F5 -> 0 | J5: =IF(ISNUMBER(I5),D5*I5,0) -> 0
A6: Pens | B6: Promotion Collateral | C6: General | D6: 0 | E6: 0 | F6: =D6+E6 -> 0 | G6: ='Item Master'!I6 -> 100 | H6: =IF(F6=0,"OUT OF STOCK",IF(F6<=G6,"REORDER","OK")) -> OUT OF STOCK | I6: ='Item Master'!F6 -> 0 | J6: =IF(ISNUMBER(I6),D6*I6,0) -> 0
A7: Diamond Grading Manual | B7: Course Collateral | C7: Diamond Graduate | D7: 0 | E7: 0 | F7: =D7+E7 -> 0 | G7: ='Item Master'!I7 -> 10 | H7: =IF(F7=0,"OUT OF STOCK",IF(F7<=G7,"REORDER","OK")) -> OUT OF STOCK | I7: ='Item Master'!F7 -> 0 | J7: =IF(ISNUMBER(I7),D7*I7,0) -> 0
A8: RBC Work Sheet | B8: Course Collateral | C8: Diamond Graduate | D8: 0 | E8: 0 | F8: =D8+E8 -> 0 | G8: ='Item Master'!I8 -> 20 | H8: =IF(F8=0,"OUT OF STOCK",IF(F8<=G8,"REORDER","OK")) -> OUT OF STOCK | I8: ='Item Master'!F8 -> 0 | J8: =IF(ISNUMBER(I8),D8*I8,0) -> 0
A9: Fancy Shape Work Sheet | B9: Course Collateral | C9: Diamond Graduate | D9: 0 | E9: 0 | F9: =D9+E9 -> 0 | G9: ='Item Master'!I9 -> 20 | H9: =IF(F9=0,"OUT OF STOCK",IF(F9<=G9,"REORDER","OK")) -> OUT OF STOCK | I9: ='Item Master'!F9 -> 0 | J9: =IF(ISNUMBER(I9),D9*I9,0) -> 0
A10: Fine Tip Tweezer | B10: Course Collateral | C10: Diamond Graduate | D10: 0 | E10: 0 | F10: =D10+E10 -> 0 | G10: ='Item Master'!I10 -> 10 | H10: =IF(F10=0,"OUT OF STOCK",IF(F10<=G10,"REORDER","OK")) -> OUT OF STOCK | I10: ='Item Master'!F10 -> 0 | J10: =IF(ISNUMBER(I10),D10*I10,0) -> 0
A11: Color Card | B11: Course Collateral | C11: Diamond Graduate | D11: 0 | E11: 0 | F11: =D11+E11 -> 0 | G11: ='Item Master'!I11 -> 10 | H11: =IF(F11=0,"OUT OF STOCK",IF(F11<=G11,"REORDER","OK")) -> OUT OF STOCK | I11: ='Item Master'!F11 -> 0 | J11: =IF(ISNUMBER(I11),D11*I11,0) -> 0
A12: Diamond Grading Kit | B12: Course Collateral | C12: Diamond Graduate | D12: 0 | E12: 0 | F12: =D12+E12 -> 0 | G12: ='Item Master'!I12 -> 5 | H12: =IF(F12=0,"OUT OF STOCK",IF(F12<=G12,"REORDER","OK")) -> OUT OF STOCK | I12: ='Item Master'!F12 -> 0 | J12: =IF(ISNUMBER(I12),D12*I12,0) -> 0
A13: Assortment Pads | B13: Classroom Equipment | C13: Diamond Graduate | D13: 0 | E13: 0 | F13: =D13+E13 -> 0 | G13: ='Item Master'!I13 -> 2 | H13: =IF(F13=0,"OUT OF STOCK",IF(F13<=G13,"REORDER","OK")) -> OUT OF STOCK | I13: ='Item Master'!F13 -> 0 | J13: =IF(ISNUMBER(I13),D13*I13,0) -> 0
A14: Grading Lamps | B14: Classroom Equipment | C14: Diamond Graduate | D14: 0 | E14: 0 | F14: =D14+E14 -> 0 | G14: ='Item Master'!I14 -> 1 | H14: =IF(F14=0,"OUT OF STOCK",IF(F14<=G14,"REORDER","OK")) -> OUT OF STOCK | I14: ='Item Master'!F14 -> 0 | J14: =IF(ISNUMBER(I14),D14*I14,0) -> 0
A15: UV Lamp | B15: Classroom Equipment | C15: Diamond Graduate | D15: 0 | E15: 0 | F15: =D15+E15 -> 0 | G15: ='Item Master'!I15 -> 1 | H15: =IF(F15=0,"OUT OF STOCK",IF(F15<=G15,"REORDER","OK")) -> OUT OF STOCK | I15: ='Item Master'!F15 -> 0 | J15: =IF(ISNUMBER(I15),D15*I15,0) -> 0
... A80: Participant Certificate | B80: Misc / Diploma | C80: General | D80: 0 | E80: 0 | F80: =D80+E80 -> 0 | G80: ='Item Master'!I80 -> 10 | H80: =IF(F80=0,"OUT OF STOCK",IF(F80<=G80,"REORDER","OK")) -> OUT OF STOCK | I80: ='Item Master'!F80 -> 0 | J80: =IF(ISNUMBER(I80),D80*I80,0) -> 0

Sheet Branch Stock Report
A1: IGI — BRANCH CURRENT STOCK REPORT
A2: CENTRE NAME: | G2: No. of Classrooms:
A3: REPORT DATE: | G3: Avg Classroom Capacity:
A4: ITEM NAME | B4: CATEGORY | C4: COURSE | D4: TYPE | E4: QTY ON HAND | F4: CONDITION (Good/Damaged/Missing) | G4: MIN REQUIRED (auto) | H4: SHORTFALL | I4: REMARKS
A5: Education Brochure | B5: Promotion Collateral | C5: General | D5: Consumable | E5: 0 | F5: Good | G5: 0 | H5: =MAX(0,G5-E5) -> 0
A6: Spiral Note Book | B6: Promotion Collateral | C6: General | D6: Consumable | E6: 0 | F6: Good | G6: 0 | H6: =MAX(0,G6-E6) -> 0
A7: Pens | B7: Promotion Collateral | C7: General | D7: Consumable | E7: 0 | F7: Good | G7: 0 | H7: =MAX(0,G7-E7) -> 0
A8: Diamond Grading Manual | B8: Course Collateral | C8: Diamond Graduate | D8: Consumable | E8: 0 | F8: Good | G8: 0 | H8: =MAX(0,G8-E8) -> 0
A9: RBC Work Sheet | B9: Course Collateral | C9: Diamond Graduate | D9: Consumable | E9: 0 | F9: Good | G9: 0 | H9: =MAX(0,G9-E9) -> 0
A10: Fancy Shape Work Sheet | B10: Course Collateral | C10: Diamond Graduate | D10: Consumable | E10: 0 | F10: Good | G10: 0 | H10: =MAX(0,G10-E10) -> 0
A11: Fine Tip Tweezer | B11: Course Collateral | C11: Diamond Graduate | D11: Consumable | E11: 0 | F11: Good | G11: 0 | H11: =MAX(0,G11-E11) -> 0
A12: Color Card | B12: Course Collateral | C12: Diamond Graduate | D12: Consumable | E12: 0 | F12: Good | G12: 0 | H12: =MAX(0,G12-E12) -> 0
A13: Diamond Grading Kit | B13: Course Collateral | C13: Diamond Graduate | D13: Kit | E13: 0 | F13: Good | G13: 0 | H13: =MAX(0,G13-E13) -> 0
A14: Assortment Pads | B14: Classroom Equipment | C14: Diamond Graduate | D14: Reusable | E14: 0 | F14: Good | G14: =4*H2 -> 0 | H14: =MAX(0,G14-E14) -> 0
A15: Grading Lamps | B15: Classroom Equipment | C15: Diamond Graduate | D15: Reusable | E15: 0 | F15: Good | G15: =6*H2 -> 0 | H15: =MAX(0,G15-E15) -> 0
A16: UV Lamp | B16: Classroom Equipment | C16: Diamond Graduate | D16: Reusable | E16: 0 | F16: Good | G16: =1*H2 -> 0 | H16: =MAX(0,G16-E16) -> 0
A17: Microscope | B17: Classroom Equipment | C17: Diamond Graduate | D17: Reusable | E17: 0 | F17: Good | G17: =2*H2 -> 0 | H17: =MAX(0,G17-E17) -> 0
A18: Dial Gauge | B18: Classroom Equipment | C18: Diamond Graduate | D18: Reusable | E18: 0 | F18: Good | G18: =2*H2 -> 0 | H18: =MAX(0,G18-E18) -> 0
A19: Jewelry Gauge | B19: Classroom Equipment | C19: Diamond Graduate | D19: Reusable | E19: 0 | F19: Good | G19: =2*H2 -> 0 | H19: =MAX(0,G19-E19) -> 0
A20: Colored Stone Manual | B20: Course Collateral | C20: Colored Stone Graduate | D20: Consumable | E20: 0 | F20: Good | G20: 0 | H20: =MAX(0,G20-E20) -> 0
A21: CS Work Sheet | B21: Course Collateral | C21: Colored Stone Graduate | D21: Consumable | E21: 0 | F21: Good | G21: 0 | H21: =MAX(0,G21-E21) -> 0
A22: Color Chart | B22: Course Collateral | C22: Colored Stone Graduate | D22: Consumable | E22: 0 | F22: Good | G22: 0 | H22: =MAX(0,G22-E22) -> 0
A23: Colored Stone Grading Kit | B23: Course Collateral | C23: Colored Stone Graduate | D23: Kit | E23: 0 | F23: Good | G23: 0 | H23: =MAX(0,G23-E23) -> 0
A24: Assortment Pads | B24: Classroom Equipment | C24: Colored Stone Graduate | D24: Reusable | E24: 0 | F24: Good | G24: =4*H2 -> 0 | H24: =MAX(0,G24-E24) -> 0
A25: Grading Lamps | B25: Classroom Equipment | C25: Colored Stone Graduate | D25: Reusable | E25: 0 | F25: Good | G25: =6*H2 -> 0 | H25: =MAX(0,G25-E25) -> 0
A26: UV Lamp | B26: Classroom Equipment | C26: Colored Stone Graduate | D26: Reusable | E26: 0 | F26: Good | G26: =1*H2 -> 0 | H26: =MAX(0,G26-E26) -> 0
A27: SG Kit / Weighing Scale | B27: Classroom Equipment | C27: Colored Stone Graduate | D27: Reusable | E27: 0 | F27: Good | G27: =1*H2 -> 0 | H27: =MAX(0,G27-E27) -> 0
A28: Microscope | B28: Classroom Equipment | C28: Colored Stone Graduate | D28: Reusable | E28: 0 | F28: Good | G28: =2*H2 -> 0 | H28: =MAX(0,G28-E28) -> 0
A29: Refractometer | B29: Classroom Equipment | C29: Colored Stone Graduate | D29: Reusable | E29: 0 | F29: Good | G29: =1*H2 -> 0 | H29: =MAX(0,G29-E29) -> 0
A30: Dichroscope | B30: Classroom Equipment | C30: Colored Stone Graduate | D30: Reusable | E30: 0 | F30: Good | G30: =1*H2 -> 0 | H30: =MAX(0,G30-E30) -> 0
A31: Polariscope | B31: Classroom Equipment | C31: Colored Stone Graduate | D31: Reusable | E31: 0 | F31: Good | G31: =1*H2 -> 0 | H31: =MAX(0,G31-E31) -> 0
A32: Jewelry Design Manual | B32: Course Collateral | C32: Jewelry Design Graduate | D32: Consumable | E32: 0 | F32: Good | G32: 0 | H32: =MAX(0,G32-E32) -> 0
A33: JD Journal / Sketch Book | B33: Course Collateral | C33: Jewelry Design Graduate | D33: Consumable | E33: 0 | F33: Good | G33: 0 | H33: =MAX(0,G33-E33) -> 0
A34: Jewelry Design Kit | B34: Course Collateral | C34: Jewelry Design Graduate | D34: Kit | E34: 0 | F34: Good | G34: 0 | H34: =MAX(0,G34-E34) -> 0
A35: Portfolio Bag | B35: Course Collateral | C35: Jewelry Design Graduate | D35: Consumable | E35: 0 | F35: Good | G35: 0 | H35: =MAX(0,G35-E35) -> 0
A36: Vellum Sheets | B36: Course Collateral | C36: Jewelry Design Graduate | D36: Consumable | E36: 0 | F36: Good | G36: 0 | H36: =MAX(0,G36-E36) -> 0
A37: A3 Black/Grey Sheets | B37: Course Collateral | C37: Jewelry Design Graduate | D37: Consumable | E37: 0 | F37: Good | G37: 0 | H37: =MAX(0,G37-E37) -> 0
A38: Sheet Protectors | B38: Course Collateral | C38: Jewelry Design Graduate | D38: Consumable | E38: 0 | F38: Good | G38: 0 | H38: =MAX(0,G38-E38) -> 0
A39: A4 Gateway Sheet | B39: Course Collateral | C39: Jewelry Design Graduate | D39: Consumable | E39: 0 | F39: Good | G39: 0 | H39: =MAX(0,G39-E39) -> 0
A40: Grading Lamps | B40: Classroom Equipment | C40: Jewelry Design Graduate | D40: Reusable | E40: 0 | F40: Good | G40: =4*H2 -> 0 | H40: =MAX(0,G40-E40) -> 0
...

Sheet Demand Projection
A1: IGI — INVENTORY DEMAND PROJECTION (6-Month Rolling)
A2: Enter expected enrollments per course per month below. Projection auto-calculates collateral requirements. Equipment projection based on branch classroom totals.
A3: ITEM NAME | B3: CATEGORY | C3: COURSE | D3: TYPE | E3: QTY PER STUDENT | F3: Jun 2026 | G3: Jul 2026 | H3: Aug 2026 | I3: Sep 2026 | J3: Oct 2026 | K3: Nov 2026 | L3: TOTAL NEEDED | M3: MUMBAI STOCK | N3: SHORTFALL
A4: ▶ Enter expected enrollments per month in Month columns for Course Collaterals
A5: Education Brochure | B5: Promotion Collateral | C5: General | D5: Consumable | E5: 1 | F5: 0 | G5: 0 | H5: 0 | I5: 0 | J5: 0 | K5: 0 | L5: =E5*SUM(F5:K5) -> 0 | M5: ='Mumbai Stock'!F4 -> 0 | N5: =MAX(0,L5-M5) -> 0
A6: Spiral Note Book | B6: Promotion Collateral | C6: General | D6: Consumable | E6: 1 | F6: 0 | G6: 0 | H6: 0 | I6: 0 | J6: 0 | K6: 0 | L6: =E6*SUM(F6:K6) -> 0 | M6: ='Mumbai Stock'!F5 -> 0 | N6: =MAX(0,L6-M6) -> 0
A7: Pens | B7: Promotion Collateral | C7: General | D7: Consumable | E7: 2 | F7: 0 | G7: 0 | H7: 0 | I7: 0 | J7: 0 | K7: 0 | L7: =E7*SUM(F7:K7) -> 0 | M7: ='Mumbai Stock'!F6 -> 0 | N7: =MAX(0,L7-M7) -> 0
A8: Diamond Grading Manual | B8: Course Collateral | C8: Diamond Graduate | D8: Consumable | E8: 1 | F8: 0 | G8: 0 | H8: 0 | I8: 0 | J8: 0 | K8: 0 | L8: =E8*SUM(F8:K8) -> 0 | M8: ='Mumbai Stock'!F7 -> 0 | N8: =MAX(0,L8-M8) -> 0
A9: RBC Work Sheet | B9: Course Collateral | C9: Diamond Graduate | D9: Consumable | E9: 2 | F9: 0 | G9: 0 | H9: 0 | I9: 0 | J9: 0 | K9: 0 | L9: =E9*SUM(F9:K9) -> 0 | M9: ='Mumbai Stock'!F8 -> 0 | N9: =MAX(0,L9-M9) -> 0
A10: Fancy Shape Work Sheet | B10: Course Collateral | C10: Diamond Graduate | D10: Consumable | E10: 2 | F10: 0 | G10: 0 | H10: 0 | I10: 0 | J10: 0 | K10: 0 | L10: =E10*SUM(F10:K10) -> 0 | M10: ='Mumbai Stock'!F9 -> 0 | N10: =MAX(0,L10-M10) -> 0
A11: Fine Tip Tweezer | B11: Course Collateral | C11: Diamond Graduate | D11: Consumable | E11: 1 | F11: 0 | G11: 0 | H11: 0 | I11: 0 | J11: 0 | K11: 0 | L11: =E11*SUM(F11:K11) -> 0 | M11: ='Mumbai Stock'!F10 -> 0 | N11: =MAX(0,L11-M11) -> 0
A12: Color Card | B12: Course Collateral | C12: Diamond Graduate | D12: Consumable | E12: 1 | F12: 0 | G12: 0 | H12: 0 | I12: 0 | J12: 0 | K12: 0 | L12: =E12*SUM(F12:K12) -> 0 | M12: ='Mumbai Stock'!F11 -> 0 | N12: =MAX(0,L12-M12) -> 0
A13: Diamond Grading Kit | B13: Course Collateral | C13: Diamond Graduate | D13: Kit | E13: 1 | F13: 0 | G13: 0 | H13: 0 | I13: 0 | J13: 0 | K13: 0 | L13: =E13*SUM(F13:K13) -> 0 | M13: ='Mumbai Stock'!F12 -> 0 | N13: =MAX(0,L13-M13) -> 0
A14: Assortment Pads | B14: Classroom Equipment | C14: Diamond Graduate | D14: Reusable | E14: 0 | F14: N/A | G14: N/A | H14: N/A | I14: N/A | J14: N/A | K14: N/A | L14: =0 -> 0 | M14: ='Mumbai Stock'!F13 -> 0 | N14: =MAX(0,L14-M14) -> 0
A15: Grading Lamps | B15: Classroom Equipment | C15: Diamond Graduate | D15: Reusable | E15: 0 | F15: N/A | G15: N/A | H15: N/A | I15: N/A | J15: N/A | K15: N/A | L15: =0 -> 0 | M15: ='Mumbai Stock'!F14 -> 0 | N15: =MAX(0,L15-M15) -> 0
A16: UV Lamp | B16: Classroom Equipment | C16: Diamond Graduate | D16: Reusable | E16: 0 | F16: N/A | G16: N/A | H16: N/A | I16: N/A | J16: N/A | K16: N/A | L16: =0 -> 0 | M16: ='Mumbai Stock'!F15 -> 0 | N16: =MAX(0,L16-M16) -> 0
A17: Microscope | B17: Classroom Equipment | C17: Diamond Graduate | D17: Reusable | E17: 0 | F17: N/A | G17: N/A | H17: N/A | I17: N/A | J17: N/A | K17: N/A | L17: =0 -> 0 | M17: ='Mumbai Stock'!F16 -> 0 | N17: =MAX(0,L17-M17) -> 0
A18: Dial Gauge | B18: Classroom Equipment | C18: Diamond Graduate | D18: Reusable | E18: 0 | F18: N/A | G18: N/A | H18: N/A | I18: N/A | J18: N/A | K18: N/A | L18: =0 -> 0 | M18: ='Mumbai Stock'!F17 -> 0 | N18: =MAX(0,L18-M18) -> 0
A19: Jewelry Gauge | B19: Classroom Equipment | C19: Diamond Graduate | D19: Reusable | E19: 0 | F19: N/A | G19: N/A | H19: N/A | I19: N/A | J19: N/A | K19: N/A | L19: =0 -> 0 | M19: ='Mumbai Stock'!F18 -> 0 | N19: =MAX(0,L19-M19) -> 0
A20: Colored Stone Manual | B20: Course Collateral | C20: Colored Stone Graduate | D20: Consumable | E20: 1 | F20: 0 | G20: 0 | H20: 0 | I20: 0 | J20: 0 | K20: 0 | L20: =E20*SUM(F20:K20) -> 0 | M20: ='Mumbai Stock'!F19 -> 0 | N20: =MAX(0,L20-M20) -> 0
A21: CS Work Sheet | B21: Course Collateral | C21: Colored Stone Graduate | D21: Consumable | E21: 2 | F21: 0 | G21: 0 | H21: 0 | I21: 0 | J21: 0 | K21: 0 | L21: =E21*SUM(F21:K21) -> 0 | M21: ='Mumbai Stock'!F20 -> 0 | N21: =MAX(0,L21-M21) -> 0
A22: Color Chart | B22: Course Collateral | C22: Colored Stone Graduate | D22: Consumable | E22: 1 | F22: 0 | G22: 0 | H22: 0 | I22: 0 | J22: 0 | K22: 0 | L22: =E22*SUM(F22:K22) -> 0 | M22: ='Mumbai Stock'!F21 -> 0 | N22: =MAX(0,L22-M22) -> 0
A23: Colored Stone Grading Kit | B23: Course Collateral | C23: Colored Stone Graduate | D23: Kit | E23: 1 | F23: 0 | G23: 0 | H23: 0 | I23: 0 | J23: 0 | K23: 0 | L23: =E23*SUM(F23:K23) -> 0 | M23: ='Mumbai Stock'!F22 -> 0 | N23: =MAX(0,L23-M23) -> 0
A24: Assortment Pads | B24: Classroom Equipment | C24: Colored Stone Graduate | D24: Reusable | E24: 0 | F24: N/A | G24: N/A | H24: N/A | I24: N/A | J24: N/A | K24: N/A | L24: =0 -> 0 | M24: ='Mumbai Stock'!F23 -> 0 | N24: =MAX(0,L24-M24) -> 0
A25: Grading Lamps | B25: Classroom Equipment | C25: Colored Stone Graduate | D25: Reusable | E25: 0 | F25: N/A | G25: N/A | H25: N/A | I25: N/A | J25: N/A | K25: N/A | L25: =0 -> 0 | M25: ='Mumbai Stock'!F24 -> 0 | N25: =MAX(0,L25-M25) -> 0
A26: UV Lamp | B26: Classroom Equipment | C26: Colored Stone Graduate | D26: Reusable | E26: 0 | F26: N/A | G26: N/A | H26: N/A | I26: N/A | J26: N/A | K26: N/A | L26: =0 -> 0 | M26: ='Mumbai Stock'!F25 -> 0 | N26: =MAX(0,L26-M26) -> 0
A27: SG Kit / Weighing Scale | B27: Classroom Equipment | C27: Colored Stone Graduate | D27: Reusable | E27: 0 | F27: N/A | G27: N/A | H27: N/A | I27: N/A | J27: N/A | K27: N/A | L27: =0 -> 0 | M27: ='Mumbai Stock'!F26 -> 0 | N27: =MAX(0,L27-M27) -> 0
A28: Microscope | B28: Classroom Equipment | C28: Colored Stone Graduate | D28: Reusable | E28: 0 | F28: N/A | G28: N/A | H28: N/A | I28: N/A | J28: N/A | K28: N/A | L28: =0 -> 0 | M28: ='Mumbai Stock'!F27 -> 0 | N28: =MAX(0,L28-M28) -> 0
A29: Refractometer | B29: Classroom Equipment | C29: Colored Stone Graduate | D29: Reusable | E29: 0 | F29: N/A | G29: N/A | H29: N/A | I29: N/A | J29: N/A | K29: N/A | L29: =0 -> 0 | M29: ='Mumbai Stock'!F28 -> 0 | N29: =MAX(0,L29-M29) -> 0
A30: Dichroscope | B30: Classroom Equipment | C30: Colored Stone Graduate | D30: Reusable | E30: 0 | F30: N/A | G30: N/A | H30: N/A | I30: N/A | J30: N/A | K30: N/A | L30: =0 -> 0 | M30: ='Mumbai Stock'!F29 -> 0 | N30: =MAX(0,L30-M30) -> 0
A31: Polariscope | B31: Classroom Equipment | C31: Colored Stone Graduate | D31: Reusable | E31: 0 | F31: N/A | G31: N/A | H31: N/A | I31: N/A | J31: N/A | K31: N/A | L31: =0 -> 0 | M31: ='Mumbai Stock'!F30 -> 0 | N31: =MAX(0,L31-M31) -> 0
A32: Jewelry Design Manual | B32: Course Collateral | C32: Jewelry Design Graduate | D32: Consumable | E32: 1 | F32: 0 | G32: 0 | H32: 0 | I32: 0 | J32: 0 | K32: 0 | L32: =E32*SUM(F32:K32) -> 0 | M32: ='Mumbai Stock'!F31 -> 0 | N32: =MAX(0,L32-M32) -> 0
A33: JD Journal / Sketch Book | B33: Course Collateral | C33: Jewelry Design Graduate | D33: Consumable | E33: 1 | F33: 0 | G33: 0 | H33: 0 | I33: 0 | J33: 0 | K33: 0 | L33: =E33*SUM(F33:K33) -> 0 | M33: ='Mumbai Stock'!F32 -> 0 | N33: =MAX(0,L33-M33) -> 0
A34: Jewelry Design Kit | B34: Course Collateral | C34: Jewelry Design Graduate | D34: Kit | E34: 1 | F34: 0 | G34: 0 | H34: 0 | I34: 0 | J34: 0 | K34: 0 | L34: =E34*SUM(F34:K34) -> 0 | M34: ='Mumbai Stock'!F33 -> 0 | N34: =MAX(0,L34-M34) -> 0
A35: Portfolio Bag | B35: Course Collateral | C35: Jewelry Design Graduate | D35: Consumable | E35: 1 | F35: 0 | G35: 0 | H35: 0 | I35: 0 | J35: 0 | K35: 0 | L35: =E35*SUM(F35:K35) -> 0 | M35: ='Mumbai Stock'!F34 -> 0 | N35: =MAX(0,L35-M35) -> 0
A36: Vellum Sheets | B36: Course Collateral | C36: Jewelry Design Graduate | D36: Consumable | E36: 10 | F36: 0 | G36: 0 | H36: 0 | I36: 0 | J36: 0 | K36: 0 | L36: =E36*SUM(F36:K36) -> 0 | M36: ='Mumbai Stock'!F35 -> 0 | N36: =MAX(0,L36-M36) -> 0
A37: A3 Black/Grey Sheets | B37: Course Collateral | C37: Jewelry Design Graduate | D37: Consumable | E37: 5 | F37: 0 | G37: 0 | H37: 0 | I37: 0 | J37: 0 | K37: 0 | L37: =E37*SUM(F37:K37) -> 0 | M37: ='Mumbai Stock'!F36 -> 0 | N37: =MAX(0,L37-M37) -> 0
A38: Sheet Protectors | B38: Course Collateral | C38: Jewelry Design Graduate | D38: Consumable | E38: 10 | F38: 0 | G38: 0 | H38: 0 | I38: 0 | J38: 0 | K38: 0 | L38: =E38*SUM(F38:K38) -> 0 | M38: ='Mumbai Stock'!F37 -> 0 | N38: =MAX(0,L38-M38) -> 0
A39: A4 Gateway Sheet | B39: Course Collateral | C39: Jewelry Design Graduate | D39: Consumable | E39: 2 | F39: 0 | G39: 0 | H39: 0 | I39: 0 | J39: 0 | K39: 0 | L39: =E39*SUM(F39:K39) -> 0 | M39: ='Mumbai Stock'!F38 -> 0 | N39: =MAX(0,L39-M39) -> 0
A40: Grading Lamps | B40: Classroom Equipment | C40: Jewelry Design Graduate | D40: Reusable | E40: 0 | F40: N/A | G40: N/A | H40: N/A | I40: N/A | J40: N/A | K40: N/A | L40: =0 -> 0 | M40: ='Mumbai Stock'!F39 -> 0 | N40: =MAX(0,L40-M40) -> 0
...

Sheet How To Use
A1: IGI INVENTORY SYSTEM — HOW TO USE THIS WORKBOOK
A3: SHEET | B3: PURPOSE | C3: WHO ACTS
A4: Item Master | B4: Central catalog of all inventory items with costs, reorder levels & lead times | C4: Mumbai HQ — fill in Unit Cost (yellow cells) once. Review reorder levels periodically.
A5: Mumbai Stock | B5: Mumbai's live stock ledger. Shows on-hand, on-order, status (OK / REORDER / OUT) | C5: Mumbai HQ — update Qty on Hand and Qty on Order whenever stock moves.
A6: Branch Stock Report | B6: Template each branch fills to report their current stock & equipment condition | C6: Branch Counsellors — fill Centre Name, Date, Classrooms, Qty on Hand, Condition monthly.
A7: Demand Projection | B7: 6-month rolling view of collateral needs based on expected enrollments | C7: Mumbai HQ or Counsellors — enter expected student enrollments per course per month. Shortfall column highlights gaps.
A9: COLOUR CODE
A10: Blue text / cells | B10: User input — fill these in
A11: Yellow cells | B11: Important inputs needing attention
A12: Green status | B12: Stock OK
A13: Yellow status | B13: Stock at or below reorder level — place order
A14: Red status | B14: Out of stock or shortfall — urgent action needed
A16: WORKFLOW
A17: Step 1 | B17: Mumbai fills Unit Cost in Item Master (yellow column F) | C17: Monthly or when costs change
A18: Step 2 | B18: Each branch fills Branch Stock Report and sends to Mumbai | C18: Monthly (1st of month)
A19: Step 3 | B19: Mumbai updates Mumbai Stock sheet with current on-hand & orders | C19: After receiving branch reports
A20: Step 4 | B20: Counsellors enter expected enrollments in Demand Projection | C20: Monthly planning cycle
A21: Step 5 | B21: Review Shortfall column — red = raise purchase order now | C21: Mumbai procurement team
A22: Step 6 | B22: Branches raise stock requisitions via the portal for dispatch | C22: As needed
